#VRML_SIM R2019a utf8
WorldInfo {
}
Viewpoint {
  orientation 0.007070729619527833 0.9999557121528897 0.006211160556187634 0.7456405256963657
  position 1.0820826687779381 0.46696319194696917 1.3717856290430213
}
TexturedBackground {
}
TexturedBackgroundLight {
}
Floor {
}
Robot {
  translation 0 0.15 0
  children [
    DEF BASE Shape {
      appearance PBRAppearance {
        baseColor 0.5411764705882353 0.8862745098039215 0.20392156862745098
      }
      geometry Box {
        size 0.1 0.3 0.1
      }
    }
    DEF HG_SOLID_1 HingeJoint {
      jointParameters HingeJointParameters {
        axis 0 1 0
        anchor 0 0.15 0
      }
      device [
        RotationalMotor {
          name "servo_motor"
          maxVelocity 13.1
          maxTorque 0.21557
        }
      ]
      endPoint DEF SOLID_1 Solid {
        translation 0 0.2 0
        children [
          Shape {
            appearance PBRAppearance {
              baseColor 0.9372549019607843 0.1607843137254902 0.1607843137254902
            }
            geometry DEF G_RED_BOX Box {
              size 0.1 0.1 0.1
            }
          }
        ]
        boundingObject USE G_RED_BOX
        physics Physics {
        }
      }
    }
  ]
  controller "robot2_Zamudio_Shadeen"
}
