#VRML_SIM R2019a utf8
WorldInfo {
}
Viewpoint {
  orientation -0.13892124021154362 0.9890544257251469 0.049721544340319355 0.5372186352675375
  position 0.674490992304337 0.48258332465353543 1.2014045834670541
}
TexturedBackground {
}
TexturedBackgroundLight {
}
Floor {
}
Robot {
  translation 0 0.15 0
  children [
    DEF BASE Shape {
      appearance PBRAppearance {
        baseColor 0.5411764705882353 0.8862745098039215 0.20392156862745098
      }
      geometry Box {
        size 0.1 0.3 0.1
      }
    }
    DEF HG_SOLID_1 HingeJoint {
      jointParameters HingeJointParameters {
        axis 0 1 0
        anchor 0 0.15 0
      }
      device [
        RotationalMotor {
          name "servo_motor"
          maxVelocity 13.1
          maxTorque 0.21557
        }
      ]
      endPoint DEF SOLID_1 Solid {
        translation 0 0.2 0
        children [
          DEF G_RED_BOX Shape {
            appearance PBRAppearance {
              baseColor 0.9372549019607843 0.1607843137254902 0.1607843137254902
            }
            geometry DEF G_RED_BOX Box {
              size 0.1 0.1 0.1
            }
          }
          DEF HG_BLUE_BOX HingeJoint {
            jointParameters DEF PR_BLUE_BOX HingeJointParameters {
              axis 0 0 1
              anchor -0.05 0.2 0
            }
            device [
              RotationalMotor {
                name "servo_motor_2"
                maxVelocity 2.1
              }
            ]
            endPoint DEF SD_RED_BOX Solid {
              translation -0.05 0.2 0
              rotation 0 0 1 0
              children [
                DEF SH_BLUE_BOX Shape {
                  appearance PBRAppearance {
                    baseColor 0.12549019607843137 0.2901960784313726 0.5294117647058824
                  }
                  geometry DEF G_BLUE_BOX Box {
                    size 0.1 0.3 0.1
                  }
                }
                DEF SH_YELLOW_HINGE HingeJoint {
                  jointParameters HingeJointParameters {
                    axis 0 0 1
                    anchor 0 0.2 -0.000119433
                  }
                  device [
                    RotationalMotor {
                      name "servo_motor_3"
                      maxVelocity 2.1
                    }
                  ]
                  endPoint Solid {
                    translation -0.1499601361042385 0.20000000000000004 -0.00011943315320173603
                    rotation 0 1 0 1.57
                    children [
                      DEF SH_BOX_YELLOW Shape {
                        appearance PBRAppearance {
                          baseColor 0.9882352941176471 0.9137254901960784 0.30980392156862746
                        }
                        geometry DEF G_SHAPE_YELLOW Box {
                          size 0.1 0.1 0.2
                        }
                      }
                    ]
                    boundingObject USE G_SHAPE_YELLOW
                    physics Physics {
                    }
                  }
                }
              ]
              boundingObject USE G_BLUE_BOX
              physics Physics {
              }
            }
          }
        ]
        boundingObject USE G_RED_BOX
        physics Physics {
        }
      }
    }
  ]
  controller "robot2_Zamudio_Shadeen"
}
